Workbook

Sheet Instrucciones
B1: VALIDADOR DE RETENCIONES DEL IMPUESTO A LA RENTA DE 5TA CATEGORÍA – PERÚ
B2: Cálculo mensual (art. 40 del Reglamento de la LIR) y anual por tramos (art. 53 de la LIR), para varios trabajadores (capacidad: 100 trabajadores y 1500 filas de ingresos).
B5: ¿QUÉ HACE ESTA PLANTILLA?
B6: • | C6: Calcula, para cada trabajador y cada mes, la retención de 5ta categoría según el art. 40 del Reglamento de la LIR: proyección de la remuneración ordinaria, gratificaciones por percibir, ingresos de meses anteriores, deducción de 7 UIT, escala progresiva por tramos y divisores.
B7: • | C7: Aplica el procedimiento para ingresos extraordinarios o pagos particulares (utilidades, bonos, reintegros, liquidaciones) en el mes en que se pagan.
B8: • | C8: Acumula ingresos y retenciones de otros empleadores (empleo simultáneo o empleador anterior en el mismo ejercicio).
B9: • | C9: Compara la retención calculada con la retención efectuada en planilla y marca las diferencias.
B10: • | C10: Resume el impuesto anual por tramos y estima el saldo de la declaración jurada anual con la deducción adicional de hasta 3 UIT.
B12: PASOS
B13: 1 | C13: Parámetros: indique el ejercicio y verifique la UIT (2026: S/ 5,500 – D.S. N° 301-2025-EF). Para otro año, agregue su UIT en la tabla 'UIT por ejercicio'.
B14: 2 | C14: Trabajadores: un trabajador por fila con código único, fechas de ingreso y cese, seguro de salud (define el % de la bonificación extraordinaria) y opciones de proyección.
B15: 3 | C15: Ingresos: una fila por concepto con código del trabajador, concepto (catálogo), origen, frecuencia, monto por pago y meses. Las columnas Ene–Dic se llenan solas según la frecuencia:
C16: – Mensual: todos los meses entre 'Mes inicio' y 'Mes fin' (vacío = diciembre).
C17: – Bimestral / Trimestral / Cuatrimestral / Semestral: cada 2 / 3 / 4 / 6 meses contados desde 'Mes inicio', hasta 'Mes fin'.
C18: – Julio y Diciembre: gratificaciones ordinarias y su bonificación extraordinaria.
C19: – Pago único: solo en el 'Mes inicio' (utilidades, bonos, reintegros, liquidación, etc.).
C20: – Ingresos variables (horas extras, comisiones): una fila 'Pago único' por mes. Aumento de sueldo: cierre la fila con 'Mes fin' y agregue otra con el nuevo monto.
C21: – Registre el mes en que el ingreso se paga o se pone a disposición (art. 57 LIR: lo percibido).
C22: – Otros empleadores: Origen = 'Otro empleador'. Sus retenciones (certificado de rentas y retenciones) con el concepto 'Retención de 5ta efectuada por otro empleador'.
B23: 4 | C23: Retenciones Planilla: digite la retención de 5ta descontada cada mes (boleta / PLAME). Deje en blanco los meses sin información.
B24: 5 | C24: Revise: 'Cálculo Mensual' (12 filas por trabajador, con filtro), 'Resumen Anual' (por trabajador y por tramos) y 'Ficha Trabajador' (elija el código en la celda amarilla).
B26: LEYENDA
B27: Dato | C27: Celda de ingreso de datos (fondo amarillo, texto azul).
B28: Fórmula | C28: Fórmula: no modificar (texto negro; columnas auxiliares en gris).
B29: Vínculo | C29: Vínculo a otra hoja (texto verde).
B30: 1,234.56 | C30: Resultado clave (fondo verde).
B31: • | C31: Resultado de la validación: 'OK' (dentro de la tolerancia), 'Retuvo de menos', 'Retuvo de más', 'No corresponde' (no hay retención calculada ni registrada), 'Sin dato planilla' o 'Revisar: sin vínculo' (hay retención en un mes sin vínculo laboral).
B33: PROCEDIMIENTO DE CÁLCULO MENSUAL (art. 40 del Reglamento de la LIR – D.S. N° 122-94-EF)
B34: a) | C34: Remuneración ordinaria del mes × meses que faltan para terminar el ejercicio (incluido el mes), más las gratificaciones ordinarias (y bonificación extraordinaria) aún no percibidas.
B35: b) | C35: Más las remuneraciones y demás ingresos afectos percibidos en los meses anteriores del ejercicio (incluye otros empleadores).
B36: c) | C36: Menos 7 UIT = renta neta anual proyectada.
B37: d) | C37: Impuesto anual proyectado con la escala progresiva acumulativa (art. 53 LIR): hasta 5 UIT 8%; más de 5 hasta 20 UIT 14%; más de 20 hasta 35 UIT 17%; más de 35 hasta 45 UIT 20%; más de 45 UIT 30%.
B38: e) | C38: Retención del mes = (impuesto anual − retenciones previas) / divisor: enero a marzo ÷ 12 (sin descontar); abril: − ret. ene–mar ÷ 9; mayo a julio: − ret. ene–abr ÷ 8; agosto: − ret. ene–jul ÷ 5; setiembre a noviembre: − ret. ene–ago ÷ 4; diciembre: regularización (impuesto anual − ret. ene–nov).
B39: f) | C39: Ingresos extraordinarios del mes (utilidades, gratificaciones o bonificaciones extraordinarias, reintegros, pagos particulares): retención adicional = impuesto con el extraordinario − impuesto sin él, sobre la misma proyección. Se suma a la retención ordinaria del mes.
B40: g) | C40: Mes de cese: impuesto sobre los ingresos percibidos hasta el cese, sin proyectar, menos todas las retenciones anteriores. Si en diciembre o en el cese lo retenido supera el impuesto, se muestra el exceso a devolver.
B42: OTROS EMPLEADORES
B43: • | C43: Empleo simultáneo: el trabajador informa al empleador que paga la mayor remuneración las rentas de los demás, para que las acumule y efectúe la retención sobre el total. Por defecto, los ingresos del otro empleador se suman conforme se perciben; si en Trabajadores marca 'Sí' en '¿Proyectar rem. ordinaria de otro empleador?', la remuneración ordinaria del otro empleador también se proyecta hasta diciembre.
B44: • | C44: Empleador anterior en el mismo ejercicio: registre sus rentas y las retenciones del certificado de rentas y retenciones; se suman a los ingresos de meses anteriores y se descuentan como retenciones ya efectuadas.
B46: SUPUESTOS Y LIMITACIONES
B47: • | C47: Retenciones de meses anteriores: según el parámetro, se descuentan las de planilla (cuando se digitaron) o las calculadas. Con 'Planilla (si existe)', un error de un mes se corrige en los meses siguientes, como ocurre en la práctica.
...

Sheet Parámetros
A1: PARÁMETROS DEL CÁLCULO
A2: Celdas amarillas: valores editables. Tasas, divisores y UIT según normativa vigente.
B4: DATOS GENERALES | D4: Equivalente S/ | E4: Comentario
B5: Empresa (razón social) | C5: EMPRESA DEMO S.A.C. | E5: Dato informativo.
B6: RUC | C6: 20000000001 | E6: Dato informativo.
B7: Ejercicio gravable | C7: 2026 | E7: Año que se valida.
B8: UIT del ejercicio (S/) | C8: =IFERROR(VLOOKUP(C7,UIT_TABLA,2,FALSE()),0) -> 5500 | E8: Se obtiene de la tabla 'UIT por ejercicio'. Si sale 0, agregue la UIT del año.
B9: Deducción fija anual (UIT) – art. 46 LIR | C9: 7 | D9: =C9*C8 -> 38500 | E9: La aplica el empleador en cada cálculo mensual.
B10: Deducción adicional máxima por gastos (UIT) – art. 46 LIR | C10: 3 | D10: =C10*C8 -> 16500 | E10: Solo para estimar la DJ anual (no la aplica el empleador).
B11: Bonificación extraordinaria Ley 30334 – EsSalud | C11: 0.09 | E11: Equivale al aporte a EsSalud sobre la gratificación.
B12: Bonificación extraordinaria Ley 30334 – EPS | C12: 0.0675 | E12: Trabajadores afiliados a una EPS.
B13: ¿Proyectar la bonificación extraordinaria con las gratificaciones? | C13: Sí | E13: Sí: se proyecta como la gratificación. No: se trata como ingreso extraordinario.
B14: Retenciones de meses anteriores que se descuentan | C14: Planilla (si existe) | E14: 'Planilla (si existe)': usa lo retenido en planilla; si falta, lo calculado.
B15: Tolerancia para validar diferencias (S/) | C15: 1 | E15: Diferencias menores o iguales se marcan como OK.
B17: ESCALA PROGRESIVA ACUMULATIVA – art. 53 LIR
B18: Tramo | C18: Desde (UIT) | D18: Hasta (UIT) | E18: Tasa | F18: Desde (S/) | G18: Hasta (S/) | H18: Tasa incremental
B19: 1 | C19: 0 | D19: 5 | E19: 0.08 | F19: =C19*UIT -> 0 | G19: =IF(D19="",1000000000000000,D19*UIT) -> 27500 | H19: =E19 -> 0.08
B20: 2 | C20: 5 | D20: 20 | E20: 0.14 | F20: =C20*UIT -> 27500 | G20: =IF(D20="",1000000000000000,D20*UIT) -> 110000 | H20: =E20-E19 -> 0.06
B21: 3 | C21: 20 | D21: 35 | E21: 0.17 | F21: =C21*UIT -> 110000 | G21: =IF(D21="",1000000000000000,D21*UIT) -> 192500 | H21: =E21-E20 -> 0.03
B22: 4 | C22: 35 | D22: 45 | E22: 0.2 | F22: =C22*UIT -> 192500 | G22: =IF(D22="",1000000000000000,D22*UIT) -> 247500 | H22: =E22-E21 -> 0.03
B23: 5 | C23: 45 | E23: 0.3 | F23: =C23*UIT -> 247500 | G23: =IF(D23="",1000000000000000,D23*UIT) -> 1e+15 | H23: =E23-E22 -> 0.1
B24: Hasta (UIT) en blanco = en adelante. La tasa incremental se usa para calcular el impuesto acumulado con SUMPRODUCT.
B26: DIVISORES MENSUALES – art. 40 Reglamento LIR (D.S. N° 122-94-EF)
B27: Mes N° | C27: Mes | D27: Divisor | E27: Descuenta retenciones hasta el mes | F27: Regla
B28: 1 | C28: Enero | D28: 12 | E28: 0 | F28: Impuesto anual / 12
B29: 2 | C29: Febrero | D29: 12 | E29: 0 | F29: Impuesto anual / 12
B30: 3 | C30: Marzo | D30: 12 | E30: 0 | F30: Impuesto anual / 12
B31: 4 | C31: Abril | D31: 9 | E31: 3 | F31: (Impuesto anual − retenciones ene–mar) / 9
B32: 5 | C32: Mayo | D32: 8 | E32: 4 | F32: (Impuesto anual − retenciones ene–abr) / 8
B33: 6 | C33: Junio | D33: 8 | E33: 4 | F33: (Impuesto anual − retenciones ene–abr) / 8
B34: 7 | C34: Julio | D34: 8 | E34: 4 | F34: (Impuesto anual − retenciones ene–abr) / 8
B35: 8 | C35: Agosto | D35: 5 | E35: 7 | F35: (Impuesto anual − retenciones ene–jul) / 5
B36: 9 | C36: Setiembre | D36: 4 | E36: 8 | F36: (Impuesto anual − retenciones ene–ago) / 4
B37: 10 | C37: Octubre | D37: 4 | E37: 8 | F37: (Impuesto anual − retenciones ene–ago) / 4
B38: 11 | C38: Noviembre | D38: 4 | E38: 8 | F38: (Impuesto anual − retenciones ene–ago) / 4
B39: 12 | C39: Diciembre | D39: 1 | E39: 11 | F39: Regularización: impuesto anual − retenciones ene–nov
B41: UIT POR EJERCICIO
B42: Año | C42: UIT (S/) | D42: Norma
B43: 2020 | C43: 4300 | D43: D.S. N° 380-2019-EF
B44: 2021 | C44: 4400 | D44: D.S. N° 392-2020-EF
...

Sheet Conceptos
A1: CATÁLOGO DE CONCEPTOS
A2: Puede agregar conceptos en las filas libres. El Tipo define el tratamiento en el cálculo (ver Parámetros > Tipos de concepto).
A4: N° | B4: Concepto | C4: Tipo | D4: Computable para gratificación | E4: Frecuencia sugerida | F4: Comentario / base legal
A5: 1 | B5: Remuneración básica / sueldo | C5: ORD | D5: Sí | E5: Mensual | F5: Remuneración ordinaria (art. 34 inc. a LIR).
A6: 2 | B6: Asignación familiar | C6: ORD | D6: Sí | E6: Mensual | F6: 10% de la RMV (Ley N° 25129).
A7: 3 | B7: Remuneración vacacional | C7: ORD | D7: Sí | E7: Mensual | F7: Sustituye a la remuneración del mes de descanso vacacional.
A8: 4 | B8: Bonificación mensual fija (cargo, convenio, etc.) | C8: ORD | D8: Sí | E8: Mensual | F8: Pago regular de cada mes.
A9: 5 | B9: Alimentación principal en dinero | C9: ORD | D9: Sí | E9: Mensual | F9: Pago regular de cada mes.
A10: 6 | B10: Horas extras | C10: ORD | D10: No | E10: Pago único | F10: Ordinaria del mes. Marque 'Sí' en computable si es regular para la gratificación.
A11: 7 | B11: Comisiones / destajo | C11: ORD | D11: No | E11: Pago único | F11: Remuneración variable del mes. Registre una fila por mes.
A12: 8 | B12: Gratificación ordinaria (Fiestas Patrias / Navidad) | C12: GRA | D12: No | E12: Julio y Diciembre | F12: Ley N° 27735.
A13: 9 | B13: Bonificación extraordinaria Ley 30334 (9% / 6.75%) | C13: BON | D13: No | E13: Julio y Diciembre | F13: Afecta a renta de 5ta; inafecta a aportaciones (Leyes N° 30334 y 30712).
A14: 10 | B14: Participación en las utilidades | C14: EXT | D14: No | E14: Pago único | F14: D. Leg. N° 892.
A15: 11 | B15: Bono / gratificación extraordinaria | C15: EXT | D15: No | E15: Pago único | F15: Pago no regular; procedimiento de ingresos extraordinarios.
A16: 12 | B16: Bono semestral (productividad, metas, etc.) | C16: EXT | D16: No | E16: Semestral | F16: No se proyecta; se grava en cada mes de pago.
A17: 13 | B17: Bono trimestral (ventas, metas, etc.) | C17: EXT | D17: No | E17: Trimestral | F17: No se proyecta; se grava en cada mes de pago.
A18: 14 | B18: Bono por cierre de pliego / convenio colectivo | C18: EXT | D18: No | E18: Pago único
A19: 15 | B19: Reintegro de remuneraciones | C19: EXT | D19: No | E19: Pago único | F19: Montos devengados en meses anteriores pagados en el mes.
A20: 16 | B20: Asignación por escolaridad / bono anual | C20: EXT | D20: No | E20: Pago único
A21: 17 | B21: Vacaciones truncas | C21: EXT | D21: No | E21: Pago único | F21: Liquidación de beneficios sociales.
A22: 18 | B22: Gratificación trunca | C22: EXT | D22: No | E22: Pago único | F22: Liquidación de beneficios sociales.
A23: 19 | B23: Remuneración de otro empleador (total del mes) | C23: ORD | D23: No | E23: Mensual | F23: Usar con Origen = 'Otro empleador' (declaración jurada del trabajador).
A24: 20 | B24: Retención de 5ta efectuada por otro empleador | C24: RET | D24: No | E24: Pago único | F24: Según certificado de rentas y retenciones. Usar con Origen = 'Otro empleador'.
A25: 21 | B25: CTS – Compensación por tiempo de servicios | C25: INA | D25: No | E25: Semestral | F25: Inafecta (art. 18 inc. c LIR).
A26: 22 | B26: Indemnización por despido arbitrario | C26: INA | D26: No | E26: Pago único | F26: Inafecta dentro del límite legal (art. 18 inc. c LIR).
A27: 23 | B27: Movilidad supeditada a la asistencia | C27: INA | D27: No | E27: Mensual | F27: Condición de trabajo; no constituye renta de 5ta.
A28: 24 | B28: Viáticos / gastos de representación sustentados | C28: INA | D28: No | E28: Pago único | F28: Gastos para el cumplimiento de funciones; no constituyen renta.
A29: 25
A30: 26
A31: 27
A32: 28
A33: 29
A34: 30
A35: 31
A36: 32
A37: 33
A38: 34
A39: 35
A40: 36
... A64: 60

Sheet Trabajadores
A1: TRABAJADORES
A2: Un trabajador por fila (capacidad: 100). Código único. No elimine filas: borre el contenido de las celdas amarillas.
A3: Las columnas grises se calculan solas. 'Gastos adicionales' (alquiler, honorarios, restaurantes, etc.) solo se usan para estimar la DJ anual.
A5: N° | B5: Código | C5: DNI | D5: Apellidos y nombres | E5: Cargo / área | F5: Fecha de ingreso | G5: Fecha de cese | H5: Seguro de salud | I5: ¿Proyectar gratificaciones? | J5: ¿Proyectar rem. ordinaria de otro empleador? | K5: Gastos adicionales sustentados – DJ (S/) | L5: Observaciones | M5: Mes inicio cálculo | N5: Mes fin cálculo | O5: ¿Cesa en el ejercicio? | P5: % bonif. extraord. | Q5: Primer mes completo | R5: Meses comput. 1er sem. | S5: Meses comput. 2do sem. | T5: Validación
A6: 1 | B6: EJ-001 | C6: 40123456 | D6: PÉREZ GARCÍA, ANA (EJEMPLO) | E6: Analista contable | F6: 43525 | H6: EsSalud | I6: Sí | J6: No | K6: 6000 | L6: Aumento desde julio, utilidades en abril, bono semestral y trimestral. | M6: =IF($B6="","",IF($F6="",1,IF(YEAR($F6)<ANIO,1,IF(YEAR($F6)=ANIO,MONTH($F6),13)))) -> 1 | N6: =IF($B6="","",IF($G6="",12,IF(YEAR($G6)>ANIO,12,IF(YEAR($G6)=ANIO,MONTH($G6),0)))) -> 12 | O6: =IF($B6="","",IF($G6="","No",IF(YEAR($G6)=ANIO,"Sí","No"))) -> No | P6: =IF($B6="","",IF($H6="EPS",BON_EPS,IF($H6="Sin bonificación",0,BON_ESSALUD))) -> 0.09 | Q6: =IF($B6="","",IF($F6="",1,IF(YEAR($F6)<ANIO,1,IF(YEAR($F6)>ANIO,13,IF(DAY($F6)=1,MONTH($F6),MONTH($F6)+1))))) -> 1 | R6: =IF($B6="","",MAX(0,MIN(6,7-$Q6))) -> 6 | S6: =IF($B6="","",MAX(0,MIN(6,13-MAX($Q6,7)))) -> 6 | T6: =IF($B6="","",IF(COUNTIF($B$6:$B$105,$B6)>1,"Código duplicado",IF($D6="","Falta nombre",IF(AND($F6<>"",$G6<>""),IF($G6<$F6,"Cese anterior al ingreso","OK"),"OK")))) -> OK
A7: 2 | B7: EJ-002 | C7: 45678912 | D7: QUISPE MAMANI, LUIS (EJEMPLO) | E7: Asistente de ventas | F7: 46143 | H7: EsSalud | I7: Sí | J7: No | K7: 3500 | L7: Ingresó en mayo; trae rentas y retenciones de su empleador anterior (ene–abr). | M7: =IF($B7="","",IF($F7="",1,IF(YEAR($F7)<ANIO,1,IF(YEAR($F7)=ANIO,MONTH($F7),13)))) -> 5 | N7: =IF($B7="","",IF($G7="",12,IF(YEAR($G7)>ANIO,12,IF(YEAR($G7)=ANIO,MONTH($G7),0)))) -> 12 | O7: =IF($B7="","",IF($G7="","No",IF(YEAR($G7)=ANIO,"Sí","No"))) -> No | P7: =IF($B7="","",IF($H7="EPS",BON_EPS,IF($H7="Sin bonificación",0,BON_ESSALUD))) -> 0.09 | Q7: =IF($B7="","",IF($F7="",1,IF(YEAR($F7)<ANIO,1,IF(YEAR($F7)>ANIO,13,IF(DAY($F7)=1,MONTH($F7),MONTH($F7)+1))))) -> 5 | R7: =IF($B7="","",MAX(0,MIN(6,7-$Q7))) -> 2 | S7: =IF($B7="","",MAX(0,MIN(6,13-MAX($Q7,7)))) -> 6 | T7: =IF($B7="","",IF(COUNTIF($B$6:$B$105,$B7)>1,"Código duplicado",IF($D7="","Falta nombre",IF(AND($F7<>"",$G7<>""),IF($G7<$F7,"Cese anterior al ingreso","OK"),"OK")))) -> OK
A8: 3 | B8: EJ-003 | C8: 70112233 | D8: TORRES ROJAS, MARÍA (EJEMPLO) | E8: Jefa de proyectos | F8: 44788 | G8: 46295 | H8: EPS | I8: Sí | J8: Sí | K8: 0 | L8: Trabajo simultáneo en otra empresa; cese el 30/09 con liquidación. | M8: =IF($B8="","",IF($F8="",1,IF(YEAR($F8)<ANIO,1,IF(YEAR($F8)=ANIO,MONTH($F8),13)))) -> 1 | N8: =IF($B8="","",IF($G8="",12,IF(YEAR($G8)>ANIO,12,IF(YEAR($G8)=ANIO,MONTH($G8),0)))) -> 9 | O8: =IF($B8="","",IF($G8="","No",IF(YEAR($G8)=ANIO,"Sí","No"))) -> Sí | P8: =IF($B8="","",IF($H8="EPS",BON_EPS,IF($H8="Sin bonificación",0,BON_ESSALUD))) -> 0.0675 | Q8: =IF($B8="","",IF($F8="",1,IF(YEAR($F8)<ANIO,1,IF(YEAR($F8)>ANIO,13,IF(DAY($F8)=1,MONTH($F8),MONTH($F8)+1))))) -> 1 | R8: =IF($B8="","",MAX(0,MIN(6,7-$Q8))) -> 6 | S8: =IF($B8="","",MAX(0,MIN(6,13-MAX($Q8,7)))) -> 6 | T8: =IF($B8="","",IF(COUNTIF($B$6:$B$105,$B8)>1,"Código duplicado",IF($D8="","Falta nombre",IF(AND($F8<>"",$G8<>""),IF($G8<$F8,"Cese anterior al ingreso","OK"),"OK")))) -> OK
A9: 4 | B9: EJ-004 | C9: 09876543 | D9: SALAZAR VEGA, CARLOS (EJEMPLO) | E9: Gerente general | F9: 42009 | H9: EsSalud | I9: Sí | J9: No | K9: 16500 | L9: Bono anual por resultados en marzo (alcanza el tramo de 30%). | M9: =IF($B9="","",IF($F9="",1,IF(YEAR($F9)<ANIO,1,IF(YEAR($F9)=ANIO,MONTH($F9),13)))) -> 1 | N9: =IF($B9="","",IF($G9="",12,IF(YEAR($G9)>ANIO,12,IF(YEAR($G9)=ANIO,MONTH($G9),0)))) -> 12 | O9: =IF($B9="","",IF($G9="","No",IF(YEAR($G9)=ANIO,"Sí","No"))) -> No | P9: =IF($B9="","",IF($H9="EPS",BON_EPS,IF($H9="Sin bonificación",0,BON_ESSALUD))) -> 0.09 | Q9: =IF($B9="","",IF($F9="",1,IF(YEAR($F9)<ANIO,1,IF(YEAR($F9)>ANIO,13,IF(DAY($F9)=1,MONTH($F9),MONTH($F9)+1))))) -> 1 | R9: =IF($B9="","",MAX(0,MIN(6,7-$Q9))) -> 6 | S9: =IF($B9="","",MAX(0,MIN(6,13-MAX($Q9,7)))) -> 6 | T9: =IF($B9="","",IF(COUNTIF($B$6:$B$105,$B9)>1,"Código duplicado",IF($D9="","Falta nombre",IF(AND($F9<>"",$G9<>""),IF($G9<$F9,"Cese anterior al ingreso","OK"),"OK")))) -> OK
A10: 5 | M10: =IF($B10="","",IF($F10="",1,IF(YEAR($F10)<ANIO,1,IF(YEAR($F10)=ANIO,MONTH($F10),13)))) | N10: =IF($B10="","",IF($G10="",12,IF(YEAR($G10)>ANIO,12,IF(YEAR($G10)=ANIO,MONTH($G10),0)))) | O10: =IF($B10="","",IF($G10="","No",IF(YEAR($G10)=ANIO,"Sí","No"))) | P10: =IF($B10="","",IF($H10="EPS",BON_EPS,IF($H10="Sin bonificación",0,BON_ESSALUD))) | Q10: =IF($B10="","",IF($F10="",1,IF(YEAR($F10)<ANIO,1,IF(YEAR($F10)>ANIO,13,IF(DAY($F10)=1,MONTH($F10),MONTH($F10)+1))))) | R10: =IF($B10="","",MAX(0,MIN(6,7-$Q10))) | S10: =IF($B10="","",MAX(0,MIN(6,13-MAX($Q10,7)))) | T10: =IF($B10="","",IF(COUNTIF($B$6:$B$105,$B10)>1,"Código duplicado",IF($D10="","Falta nombre",IF(AND($F10<>"",$G10<>""),IF($G10<$F10,"Cese anterior al ingreso","OK"),"OK"))))
A11: 6 | M11: =IF($B11="","",IF($F11="",1,IF(YEAR($F11)<ANIO,1,IF(YEAR($F11)=ANIO,MONTH($F11),13)))) | N11: =IF($B11="","",IF($G11="",12,IF(YEAR($G11)>ANIO,12,IF(YEAR($G11)=ANIO,MONTH($G11),0)))) | O11: =IF($B11="","",IF($G11="","No",IF(YEAR($G11)=ANIO,"Sí","No"))) | P11: =IF($B11="","",IF($H11="EPS",BON_EPS,IF($H11="Sin bonificación",0,BON_ESSALUD))) | Q11: =IF($B11="","",IF($F11="",1,IF(YEAR($F11)<ANIO,1,IF(YEAR($F11)>ANIO,13,IF(DAY($F11)=1,MONTH($F11),MONTH($F11)+1))))) | R11: =IF($B11="","",MAX(0,MIN(6,7-$Q11))) | S11: =IF($B11="","",MAX(0,MIN(6,13-MAX($Q11,7)))) | T11: =IF($B11="","",IF(COUNTIF($B$6:$B$105,$B11)>1,"Código duplicado",IF($D11="","Falta nombre",IF(AND($F11<>"",$G11<>""),IF($G11<$F11,"Cese anterior al ingreso","OK"),"OK"))))
A12: 7 | M12: =IF($B12="","",IF($F12="",1,IF(YEAR($F12)<ANIO,1,IF(YEAR($F12)=ANIO,MONTH($F12),13)))) | N12: =IF($B12="","",IF($G12="",12,IF(YEAR($G12)>ANIO,12,IF(YEAR($G12)=ANIO,MONTH($G12),0)))) | O12: =IF($B12="","",IF($G12="","No",IF(YEAR($G12)=ANIO,"Sí","No"))) | P12: =IF($B12="","",IF($H12="EPS",BON_EPS,IF($H12="Sin bonificación",0,BON_ESSALUD))) | Q12: =IF($B12="","",IF($F12="",1,IF(YEAR($F12)<ANIO,1,IF(YEAR($F12)>ANIO,13,IF(DAY($F12)=1,MONTH($F12),MONTH($F12)+1))))) | R12: =IF($B12="","",MAX(0,MIN(6,7-$Q12))) | S12: =IF($B12="","",MAX(0,MIN(6,13-MAX($Q12,7)))) | T12: =IF($B12="","",IF(COUNTIF($B$6:$B$105,$B12)>1,"Código duplicado",IF($D12="","Falta nombre",IF(AND($F12<>"",$G12<>""),IF($G12<$F12,"Cese anterior al ingreso","OK"),"OK"))))
A13: 8 | M13: =IF($B13="","",IF($F13="",1,IF(YEAR($F13)<ANIO,1,IF(YEAR($F13)=ANIO,MONTH($F13),13)))) | N13: =IF($B13="","",IF($G13="",12,IF(YEAR($G13)>ANIO,12,IF(YEAR($G13)=ANIO,MONTH($G13),0)))) | O13: =IF($B13="","",IF($G13="","No",IF(YEAR($G13)=ANIO,"Sí","No"))) | P13: =IF($B13="","",IF($H13="EPS",BON_EPS,IF($H13="Sin bonificación",0,BON_ESSALUD))) | Q13: =IF($B13="","",IF($F13="",1,IF(YEAR($F13)<ANIO,1,IF(YEAR($F13)>ANIO,13,IF(DAY($F13)=1,MONTH($F13),MONTH($F13)+1))))) | R13: =IF($B13="","",MAX(0,MIN(6,7-$Q13))) | S13: =IF($B13="","",MAX(0,MIN(6,13-MAX($Q13,7)))) | T13: =IF($B13="","",IF(COUNTIF($B$6:$B$105,$B13)>1,"Código duplicado",IF($D13="","Falta nombre",IF(AND($F13<>"",$G13<>""),IF($G13<$F13,"Cese anterior al ingreso","OK"),"OK"))))
A14: 9 | M14: =IF($B14="","",IF($F14="",1,IF(YEAR($F14)<ANIO,1,IF(YEAR($F14)=ANIO,MONTH($F14),13)))) | N14: =IF($B14="","",IF($G14="",12,IF(YEAR($G14)>ANIO,12,IF(YEAR($G14)=ANIO,MONTH($G14),0)))) | O14: =IF($B14="","",IF($G14="","No",IF(YEAR($G14)=ANIO,"Sí","No"))) | P14: =IF($B14="","",IF($H14="EPS",BON_EPS,IF($H14="Sin bonificación",0,BON_ESSALUD))) | Q14: =IF($B14="","",IF($F14="",1,IF(YEAR($F14)<ANIO,1,IF(YEAR($F14)>ANIO,13,IF(DAY($F14)=1,MONTH($F14),MONTH($F14)+1))))) | R14: =IF($B14="","",MAX(0,MIN(6,7-$Q14))) | S14: =IF($B14="","",MAX(0,MIN(6,13-MAX($Q14,7)))) | T14: =IF($B14="","",IF(COUNTIF($B$6:$B$105,$B14)>1,"Código duplicado",IF($D14="","Falta nombre",IF(AND($F14<>"",$G14<>""),IF($G14<$F14,"Cese anterior al ingreso","OK"),"OK"))))
A15: 10 | M15: =IF($B15="","",IF($F15="",1,IF(YEAR($F15)<ANIO,1,IF(YEAR($F15)=ANIO,MONTH($F15),13)))) | N15: =IF($B15="","",IF($G15="",12,IF(YEAR($G15)>ANIO,12,IF(YEAR($G15)=ANIO,MONTH($G15),0)))) | O15: =IF($B15="","",IF($G15="","No",IF(YEAR($G15)=ANIO,"Sí","No"))) | P15: =IF($B15="","",IF($H15="EPS",BON_EPS,IF($H15="Sin bonificación",0,BON_ESSALUD))) | Q15: =IF($B15="","",IF($F15="",1,IF(YEAR($F15)<ANIO,1,IF(YEAR($F15)>ANIO,13,IF(DAY($F15)=1,MONTH($F15),MONTH($F15)+1))))) | R15: =IF($B15="","",MAX(0,MIN(6,7-$Q15))) | S15: =IF($B15="","",MAX(0,MIN(6,13-MAX($Q15,7)))) | T15: =IF($B15="","",IF(COUNTIF($B$6:$B$105,$B15)>1,"Código duplicado",IF($D15="","Falta nombre",IF(AND($F15<>"",$G15<>""),IF($G15<$F15,"Cese anterior al ingreso","OK"),"OK"))))
A16: 11 | M16: =IF($B16="","",IF($F16="",1,IF(YEAR($F16)<ANIO,1,IF(YEAR($F16)=ANIO,MONTH($F16),13)))) | N16: =IF($B16="","",IF($G16="",12,IF(YEAR($G16)>ANIO,12,IF(YEAR($G16)=ANIO,MONTH($G16),0)))) | O16: =IF($B16="","",IF($G16="","No",IF(YEAR($G16)=ANIO,"Sí","No"))) | P16: =IF($B16="","",IF($H16="EPS",BON_EPS,IF($H16="Sin bonificación",0,BON_ESSALUD))) | Q16: =IF($B16="","",IF($F16="",1,IF(YEAR($F16)<ANIO,1,IF(YEAR($F16)>ANIO,13,IF(DAY($F16)=1,MONTH($F16),MONTH($F16)+1))))) | R16: =IF($B16="","",MAX(0,MIN(6,7-$Q16))) | S16: =IF($B16="","",MAX(0,MIN(6,13-MAX($Q16,7)))) | T16: =IF($B16="","",IF(COUNTIF($B$6:$B$105,$B16)>1,"Código duplicado",IF($D16="","Falta nombre",IF(AND($F16<>"",$G16<>""),IF($G16<$F16,"Cese anterior al ingreso","OK"),"OK"))))
A17: 12 | M17: =IF($B17="","",IF($F17="",1,IF(YEAR($F17)<ANIO,1,IF(YEAR($F17)=ANIO,MONTH($F17),13)))) | N17: =IF($B17="","",IF($G17="",12,IF(YEAR($G17)>ANIO,12,IF(YEAR($G17)=ANIO,MONTH($G17),0)))) | O17: =IF($B17="","",IF($G17="","No",IF(YEAR($G17)=ANIO,"Sí","No"))) | P17: =IF($B17="","",IF($H17="EPS",BON_EPS,IF($H17="Sin bonificación",0,BON_ESSALUD))) | Q17: =IF($B17="","",IF($F17="",1,IF(YEAR($F17)<ANIO,1,IF(YEAR($F17)>ANIO,13,IF(DAY($F17)=1,MONTH($F17),MONTH($F17)+1))))) | R17: =IF($B17="","",MAX(0,MIN(6,7-$Q17))) | S17: =IF($B17="","",MAX(0,MIN(6,13-MAX($Q17,7)))) | T17: =IF($B17="","",IF(COUNTIF($B$6:$B$105,$B17)>1,"Código duplicado",IF($D17="","Falta nombre",IF(AND($F17<>"",$G17<>""),IF($G17<$F17,"Cese anterior al ingreso","OK"),"OK"))))
A18: 13 | M18: =IF($B18="","",IF($F18="",1,IF(YEAR($F18)<ANIO,1,IF(YEAR($F18)=ANIO,MONTH($F18),13)))) | N18: =IF($B18="","",IF($G18="",12,IF(YEAR($G18)>ANIO,12,IF(YEAR($G18)=ANIO,MONTH($G18),0)))) | O18: =IF($B18="","",IF($G18="","No",IF(YEAR($G18)=ANIO,"Sí","No"))) | P18: =IF($B18="","",IF($H18="EPS",BON_EPS,IF($H18="Sin bonificación",0,BON_ESSALUD))) | Q18: =IF($B18="","",IF($F18="",1,IF(YEAR($F18)<ANIO,1,IF(YEAR($F18)>ANIO,13,IF(DAY($F18)=1,MONTH($F18),MONTH($F18)+1))))) | R18: =IF($B18="","",MAX(0,MIN(6,7-$Q18))) | S18: =IF($B18="","",MAX(0,MIN(6,13-MAX($Q18,7)))) | T18: =IF($B18="","",IF(COUNTIF($B$6:$B$105,$B18)>1,"Código duplicado",IF($D18="","Falta nombre",IF(AND($F18<>"",$G18<>""),IF($G18<$F18,"Cese anterior al ingreso","OK"),"OK"))))
A19: 14 | M19: =IF($B19="","",IF($F19="",1,IF(YEAR($F19)<ANIO,1,IF(YEAR($F19)=ANIO,MONTH($F19),13)))) | N19: =IF($B19="","",IF($G19="",12,IF(YEAR($G19)>ANIO,12,IF(YEAR($G19)=ANIO,MONTH($G19),0)))) | O19: =IF($B19="","",IF($G19="","No",IF(YEAR($G19)=ANIO,"Sí","No"))) | P19: =IF($B19="","",IF($H19="EPS",BON_EPS,IF($H19="Sin bonificación",0,BON_ESSALUD))) | Q19: =IF($B19="","",IF($F19="",1,IF(YEAR($F19)<ANIO,1,IF(YEAR($F19)>ANIO,13,IF(DAY($F19)=1,MONTH($F19),MONTH($F19)+1))))) | R19: =IF($B19="","",MAX(0,MIN(6,7-$Q19))) | S19: =IF($B19="","",MAX(0,MIN(6,13-MAX($Q19,7)))) | T19: =IF($B19="","",IF(COUNTIF($B$6:$B$105,$B19)>1,"Código duplicado",IF($D19="","Falta nombre",IF(AND($F19<>"",$G19<>""),IF($G19<$F19,"Cese anterior al ingreso","OK"),"OK"))))
A20: 15 | M20: =IF($B20="","",IF($F20="",1,IF(YEAR($F20)<ANIO,1,IF(YEAR($F20)=ANIO,MONTH($F20),13)))) | N20: =IF($B20="","",IF($G20="",12,IF(YEAR($G20)>ANIO,12,IF(YEAR($G20)=ANIO,MONTH($G20),0)))) | O20: =IF($B20="","",IF($G20="","No",IF(YEAR($G20)=ANIO,"Sí","No"))) | P20: =IF($B20="","",IF($H20="EPS",BON_EPS,IF($H20="Sin bonificación",0,BON_ESSALUD))) | Q20: =IF($B20="","",IF($F20="",1,IF(YEAR($F20)<ANIO,1,IF(YEAR($F20)>ANIO,13,IF(DAY($F20)=1,MONTH($F20),MONTH($F20)+1))))) | R20: =IF($B20="","",MAX(0,MIN(6,7-$Q20))) | S20: =IF($B20="","",MAX(0,MIN(6,13-MAX($Q20,7)))) | T20: =IF($B20="","",IF(COUNTIF($B$6:$B$105,$B20)>1,"Código duplicado",IF($D20="","Falta nombre",IF(AND($F20<>"",$G20<>""),IF($G20<$F20,"Cese anterior al ingreso","OK"),"OK"))))
A21: 16 | M21: =IF($B21="","",IF($F21="",1,IF(YEAR($F21)<ANIO,1,IF(YEAR($F21)=ANIO,MONTH($F21),13)))) | N21: =IF($B21="","",IF($G21="",12,IF(YEAR($G21)>ANIO,12,IF(YEAR($G21)=ANIO,MONTH($G21),0)))) | O21: =IF($B21="","",IF($G21="","No",IF(YEAR($G21)=ANIO,"Sí","No"))) | P21: =IF($B21="","",IF($H21="EPS",BON_EPS,IF($H21="Sin bonificación",0,BON_ESSALUD))) | Q21: =IF($B21="","",IF($F21="",1,IF(YEAR($F21)<ANIO,1,IF(YEAR($F21)>ANIO,13,IF(DAY($F21)=1,MONTH($F21),MONTH($F21)+1))))) | R21: =IF($B21="","",MAX(0,MIN(6,7-$Q21))) | S21: =IF($B21="","",MAX(0,MIN(6,13-MAX($Q21,7)))) | T21: =IF($B21="","",IF(COUNTIF($B$6:$B$105,$B21)>1,"Código duplicado",IF($D21="","Falta nombre",IF(AND($F21<>"",$G21<>""),IF($G21<$F21,"Cese anterior al ingreso","OK"),"OK"))))
... A105: 100 | M105: =IF($B105="","",IF($F105="",1,IF(YEAR($F105)<ANIO,1,IF(YEAR($F105)=ANIO,MONTH($F105),13)))) | N105: =IF($B105="","",IF($G105="",12,IF(YEAR($G105)>ANIO,12,IF(YEAR($G105)=ANIO,MONTH($G105),0)))) | O105: =IF($B105="","",IF($G105="","No",IF(YEAR($G105)=ANIO,"Sí","No"))) | P105: =IF($B105="","",IF($H105="EPS",BON_EPS,IF($H105="Sin bonificación",0,BON_ESSALUD))) | Q105: =IF($B105="","",IF($F105="",1,IF(YEAR($F105)<ANIO,1,IF(YEAR($F105)>ANIO,13,IF(DAY($F105)=1,MONTH($F105),MONTH($F105)+1))))) | R105: =IF($B105="","",MAX(0,MIN(6,7-$Q105))) | S105: =IF($B105="","",MAX(0,MIN(6,13-MAX($Q105,7)))) | T105: =IF($B105="","",IF(COUNTIF($B$6:$B$105,$B105)>1,"Código duplicado",IF($D105="","Falta nombre",IF(AND($F105<>"",$G105<>""),IF($G105<$F105,"Cese anterior al ingreso","OK"),"OK"))))

Sheet Ingresos
A1: REGISTRO DE INGRESOS
A2: Una fila por concepto. Elija la frecuencia y la plantilla distribuye el monto en los meses de pago (Ene–Dic). Registre el mes en que se paga (criterio de lo percibido).
A3: Ingresos variables (horas extras, comisiones): una fila 'Pago único' por mes. Cambio de sueldo: cierre la fila con 'Mes fin' y cree otra con el nuevo monto. Otros empleadores: Origen = 'Otro empleador'.
A5: N° | B5: Código trabajador | C5: Trabajador | D5: Concepto | E5: Tipo | F5: Comp. grat. | G5: Origen | H5: Otro empleador (RUC – razón social) | I5: Frecuencia | J5: Monto por pago (S/) | K5: Mes inicio / pago (1-12) | L5: Mes fin (1-12) | M5: Clase | N5: Cada (meses) | O5: Ene | P5: Feb | Q5: Mar | R5: Abr | S5: May | T5: Jun | U5: Jul | V5: Ago | W5: Set | X5: Oct | Y5: Nov | Z5: Dic | AA5: Total año | AB5: Validación
A6: 1 | B6: EJ-001 | C6: =IF($B6="","",IFERROR(INDEX(Trabajadores!$D$6:$D$105,MATCH($B6,LST_COD,0)),"¿Código?")) -> PÉREZ GARCÍA, ANA (EJEMPLO) | D6: Remuneración básica / sueldo | E6: =IF($D6="","",IFERROR(VLOOKUP($D6,CONC_TABLA,2,FALSE()),"")) -> ORD | F6: =IF($D6="","",IFERROR(VLOOKUP($D6,CONC_TABLA,3,FALSE()),"")) -> Sí | G6: Empresa principal | I6: Mensual | J6: 8500 | K6: 1 | L6: 6 | M6: =IF(OR($B6="",$E6=""),"",IF($E6="INA","INA",IF($G6="Otro empleador",IF($E6="RET","RETO",IF($E6="ORD","OTO","OTX")),IF($E6="RET","ERR",$E6)))) -> ORD | N6: =IF($I6="","",IFERROR(VLOOKUP($I6,FREC_TABLA,2,FALSE()),"")) -> 1 | O6: =IF(OR($M6="",$M6="ERR",$J6="",$K6="",$N6=""),0,IF($N6=0,IF(AND(OR(1=7,1=12),1>=$K6,1<=IF($L6="",12,$L6)),$J6,0),IF(AND(1>=$K6,1<=IF($L6="",12,$L6),MOD(1-$K6,$N6)=0),$J6,0))) -> 8500 | P6: =IF(OR($M6="",$M6="ERR",$J6="",$K6="",$N6=""),0,IF($N6=0,IF(AND(OR(2=7,2=12),2>=$K6,2<=IF($L6="",12,$L6)),$J6,0),IF(AND(2>=$K6,2<=IF($L6="",12,$L6),MOD(2-$K6,$N6)=0),$J6,0))) -> 8500 | Q6: =IF(OR($M6="",$M6="ERR",$J6="",$K6="",$N6=""),0,IF($N6=0,IF(AND(OR(3=7,3=12),3>=$K6,3<=IF($L6="",12,$L6)),$J6,0),IF(AND(3>=$K6,3<=IF($L6="",12,$L6),MOD(3-$K6,$N6)=0),$J6,0))) -> 8500 | R6: =IF(OR($M6="",$M6="ERR",$J6="",$K6="",$N6=""),0,IF($N6=0,IF(AND(OR(4=7,4=12),4>=$K6,4<=IF($L6="",12,$L6)),$J6,0),IF(AND(4>=$K6,4<=IF($L6="",12,$L6),MOD(4-$K6,$N6)=0),$J6,0))) -> 8500 | S6: =IF(OR($M6="",$M6="ERR",$J6="",$K6="",$N6=""),0,IF($N6=0,IF(AND(OR(5=7,5=12),5>=$K6,5<=IF($L6="",12,$L6)),$J6,0),IF(AND(5>=$K6,5<=IF($L6="",12,$L6),MOD(5-$K6,$N6)=0),$J6,0))) -> 8500 | T6: =IF(OR($M6="",$M6="ERR",$J6="",$K6="",$N6=""),0,IF($N6=0,IF(AND(OR(6=7,6=12),6>=$K6,6<=IF($L6="",12,$L6)),$J6,0),IF(AND(6>=$K6,6<=IF($L6="",12,$L6),MOD(6-$K6,$N6)=0),$J6,0))) -> 8500 | U6: =IF(OR($M6="",$M6="ERR",$J6="",$K6="",$N6=""),0,IF($N6=0,IF(AND(OR(7=7,7=12),7>=$K6,7<=IF($L6="",12,$L6)),$J6,0),IF(AND(7>=$K6,7<=IF($L6="",12,$L6),MOD(7-$K6,$N6)=0),$J6,0))) -> 0 | V6: =IF(OR($M6="",$M6="ERR",$J6="",$K6="",$N6=""),0,IF($N6=0,IF(AND(OR(8=7,8=12),8>=$K6,8<=IF($L6="",12,$L6)),$J6,0),IF(AND(8>=$K6,8<=IF($L6="",12,$L6),MOD(8-$K6,$N6)=0),$J6,0))) -> 0 | W6: =IF(OR($M6="",$M6="ERR",$J6="",$K6="",$N6=""),0,IF($N6=0,IF(AND(OR(9=7,9=12),9>=$K6,9<=IF($L6="",12,$L6)),$J6,0),IF(AND(9>=$K6,9<=IF($L6="",12,$L6),MOD(9-$K6,$N6)=0),$J6,0))) -> 0 | X6: =IF(OR($M6="",$M6="ERR",$J6="",$K6="",$N6=""),0,IF($N6=0,IF(AND(OR(10=7,10=12),10>=$K6,10<=IF($L6="",12,$L6)),$J6,0),IF(AND(10>=$K6,10<=IF($L6="",12,$L6),MOD(10-$K6,$N6)=0),$J6,0))) -> 0 | Y6: =IF(OR($M6="",$M6="ERR",$J6="",$K6="",$N6=""),0,IF($N6=0,IF(AND(OR(11=7,11=12),11>=$K6,11<=IF($L6="",12,$L6)),$J6,0),IF(AND(11>=$K6,11<=IF($L6="",12,$L6),MOD(11-$K6,$N6)=0),$J6,0))) -> 0 | Z6: =IF(OR($M6="",$M6="ERR",$J6="",$K6="",$N6=""),0,IF($N6=0,IF(AND(OR(12=7,12=12),12>=$K6,12<=IF($L6="",12,$L6)),$J6,0),IF(AND(12>=$K6,12<=IF($L6="",12,$L6),MOD(12-$K6,$N6)=0),$J6,0))) -> 0 | AA6: =SUM(O6:Z6) -> 51000 | AB6: =IF(AND($B6="",$D6="",$J6=""),"",IF($B6="","Falta código",IF(ISNA(MATCH($B6,LST_COD,0)),"Código no registrado en Trabajadores",IF($E6="","Concepto no está en el catálogo",IF($M6="ERR","Retención de otro empleador: Origen = Otro empleador",IF(OR($J6="",$K6=""),"Falta monto o mes",IF(OR($K6<1,$K6>12),"Mes inicio inválido",IF(AND($L6<>"",OR($L6<$K6,$L6>12)),"Mes fin inválido",IF($N6="","Falta frecuencia",IF(AND($G6<>"Otro empleador",SUMPRODUCT(($O6:$Z6<>0)*(((COLUMN($O6:$Z6)-14)<INDEX(Trabajadores!$M$6:$M$105,MATCH($B6,LST_COD,0)))+((COLUMN($O6:$Z6)-14)>INDEX(Trabajadores!$N$6:$N$105,MATCH($B6,LST_COD,0)))))>0),"Aviso: hay meses fuera del periodo laboral","OK")))))))))) -> OK
A7: 2 | B7: EJ-001 | C7: =IF($B7="","",IFERROR(INDEX(Trabajadores!$D$6:$D$105,MATCH($B7,LST_COD,0)),"¿Código?")) -> PÉREZ GARCÍA, ANA (EJEMPLO) | D7: Remuneración básica / sueldo | E7: =IF($D7="","",IFERROR(VLOOKUP($D7,CONC_TABLA,2,FALSE()),"")) -> ORD | F7: =IF($D7="","",IFERROR(VLOOKUP($D7,CONC_TABLA,3,FALSE()),"")) -> Sí | G7: Empresa principal | I7: Mensual | J7: 9000 | K7: 7 | L7: 12 | M7: =IF(OR($B7="",$E7=""),"",IF($E7="INA","INA",IF($G7="Otro empleador",IF($E7="RET","RETO",IF($E7="ORD","OTO","OTX")),IF($E7="RET","ERR",$E7)))) -> ORD | N7: =IF($I7="","",IFERROR(VLOOKUP($I7,FREC_TABLA,2,FALSE()),"")) -> 1 | O7: =IF(OR($M7="",$M7="ERR",$J7="",$K7="",$N7=""),0,IF($N7=0,IF(AND(OR(1=7,1=12),1>=$K7,1<=IF($L7="",12,$L7)),$J7,0),IF(AND(1>=$K7,1<=IF($L7="",12,$L7),MOD(1-$K7,$N7)=0),$J7,0))) -> 0 | P7: =IF(OR($M7="",$M7="ERR",$J7="",$K7="",$N7=""),0,IF($N7=0,IF(AND(OR(2=7,2=12),2>=$K7,2<=IF($L7="",12,$L7)),$J7,0),IF(AND(2>=$K7,2<=IF($L7="",12,$L7),MOD(2-$K7,$N7)=0),$J7,0))) -> 0 | Q7: =IF(OR($M7="",$M7="ERR",$J7="",$K7="",$N7=""),0,IF($N7=0,IF(AND(OR(3=7,3=12),3>=$K7,3<=IF($L7="",12,$L7)),$J7,0),IF(AND(3>=$K7,3<=IF($L7="",12,$L7),MOD(3-$K7,$N7)=0),$J7,0))) -> 0 | R7: =IF(OR($M7="",$M7="ERR",$J7="",$K7="",$N7=""),0,IF($N7=0,IF(AND(OR(4=7,4=12),4>=$K7,4<=IF($L7="",12,$L7)),$J7,0),IF(AND(4>=$K7,4<=IF($L7="",12,$L7),MOD(4-$K7,$N7)=0),$J7,0))) -> 0 | S7: =IF(OR($M7="",$M7="ERR",$J7="",$K7="",$N7=""),0,IF($N7=0,IF(AND(OR(5=7,5=12),5>=$K7,5<=IF($L7="",12,$L7)),$J7,0),IF(AND(5>=$K7,5<=IF($L7="",12,$L7),MOD(5-$K7,$N7)=0),$J7,0))) -> 0 | T7: =IF(OR($M7="",$M7="ERR",$J7="",$K7="",$N7=""),0,IF($N7=0,IF(AND(OR(6=7,6=12),6>=$K7,6<=IF($L7="",12,$L7)),$J7,0),IF(AND(6>=$K7,6<=IF($L7="",12,$L7),MOD(6-$K7,$N7)=0),$J7,0))) -> 0 | U7: =IF(OR($M7="",$M7="ERR",$J7="",$K7="",$N7=""),0,IF($N7=0,IF(AND(OR(7=7,7=12),7>=$K7,7<=IF($L7="",12,$L7)),$J7,0),IF(AND(7>=$K7,7<=IF($L7="",12,$L7),MOD(7-$K7,$N7)=0),$J7,0))) -> 9000 | V7: =IF(OR($M7="",$M7="ERR",$J7="",$K7="",$N7=""),0,IF($N7=0,IF(AND(OR(8=7,8=12),8>=$K7,8<=IF($L7="",12,$L7)),$J7,0),IF(AND(8>=$K7,8<=IF($L7="",12,$L7),MOD(8-$K7,$N7)=0),$J7,0))) -> 9000 | W7: =IF(OR($M7="",$M7="ERR",$J7="",$K7="",$N7=""),0,IF($N7=0,IF(AND(OR(9=7,9=12),9>=$K7,9<=IF($L7="",12,$L7)),$J7,0),IF(AND(9>=$K7,9<=IF($L7="",12,$L7),MOD(9-$K7,$N7)=0),$J7,0))) -> 9000 | X7: =IF(OR($M7="",$M7="ERR",$J7="",$K7="",$N7=""),0,IF($N7=0,IF(AND(OR(10=7,10=12),10>=$K7,10<=IF($L7="",12,$L7)),$J7,0),IF(AND(10>=$K7,10<=IF($L7="",12,$L7),MOD(10-$K7,$N7)=0),$J7,0))) -> 9000 | Y7: =IF(OR($M7="",$M7="ERR",$J7="",$K7="",$N7=""),0,IF($N7=0,IF(AND(OR(11=7,11=12),11>=$K7,11<=IF($L7="",12,$L7)),$J7,0),IF(AND(11>=$K7,11<=IF($L7="",12,$L7),MOD(11-$K7,$N7)=0),$J7,0))) -> 9000 | Z7: =IF(OR($M7="",$M7="ERR",$J7="",$K7="",$N7=""),0,IF($N7=0,IF(AND(OR(12=7,12=12),12>=$K7,12<=IF($L7="",12,$L7)),$J7,0),IF(AND(12>=$K7,12<=IF($L7="",12,$L7),MOD(12-$K7,$N7)=0),$J7,0))) -> 9000 | AA7: =SUM(O7:Z7) -> 54000 | AB7: =IF(AND($B7="",$D7="",$J7=""),"",IF($B7="","Falta código",IF(ISNA(MATCH($B7,LST_COD,0)),"Código no registrado en Trabajadores",IF($E7="","Concepto no está en el catálogo",IF($M7="ERR","Retención de otro empleador: Origen = Otro empleador",IF(OR($J7="",$K7=""),"Falta monto o mes",IF(OR($K7<1,$K7>12),"Mes inicio inválido",IF(AND($L7<>"",OR($L7<$K7,$L7>12)),"Mes fin inválido",IF($N7="","Falta frecuencia",IF(AND($G7<>"Otro empleador",SUMPRODUCT(($O7:$Z7<>0)*(((COLUMN($O7:$Z7)-14)<INDEX(Trabajadores!$M$6:$M$105,MATCH($B7,LST_COD,0)))+((COLUMN($O7:$Z7)-14)>INDEX(Trabajadores!$N$6:$N$105,MATCH($B7,LST_COD,0)))))>0),"Aviso: hay meses fuera del periodo laboral","OK")))))))))) -> OK
A8: 3 | B8: EJ-001 | C8: =IF($B8="","",IFERROR(INDEX(Trabajadores!$D$6:$D$105,MATCH($B8,LST_COD,0)),"¿Código?")) -> PÉREZ GARCÍA, ANA (EJEMPLO) | D8: Asignación familiar | E8: =IF($D8="","",IFERROR(VLOOKUP($D8,CONC_TABLA,2,FALSE()),"")) -> ORD | F8: =IF($D8="","",IFERROR(VLOOKUP($D8,CONC_TABLA,3,FALSE()),"")) -> Sí | G8: Empresa principal | I8: Mensual | J8: 113 | K8: 1 | L8: 12 | M8: =IF(OR($B8="",$E8=""),"",IF($E8="INA","INA",IF($G8="Otro empleador",IF($E8="RET","RETO",IF($E8="ORD","OTO","OTX")),IF($E8="RET","ERR",$E8)))) -> ORD | N8: =IF($I8="","",IFERROR(VLOOKUP($I8,FREC_TABLA,2,FALSE()),"")) -> 1 | O8: =IF(OR($M8="",$M8="ERR",$J8="",$K8="",$N8=""),0,IF($N8=0,IF(AND(OR(1=7,1=12),1>=$K8,1<=IF($L8="",12,$L8)),$J8,0),IF(AND(1>=$K8,1<=IF($L8="",12,$L8),MOD(1-$K8,$N8)=0),$J8,0))) -> 113 | P8: =IF(OR($M8="",$M8="ERR",$J8="",$K8="",$N8=""),0,IF($N8=0,IF(AND(OR(2=7,2=12),2>=$K8,2<=IF($L8="",12,$L8)),$J8,0),IF(AND(2>=$K8,2<=IF($L8="",12,$L8),MOD(2-$K8,$N8)=0),$J8,0))) -> 113 | Q8: =IF(OR($M8="",$M8="ERR",$J8="",$K8="",$N8=""),0,IF($N8=0,IF(AND(OR(3=7,3=12),3>=$K8,3<=IF($L8="",12,$L8)),$J8,0),IF(AND(3>=$K8,3<=IF($L8="",12,$L8),MOD(3-$K8,$N8)=0),$J8,0))) -> 113 | R8: =IF(OR($M8="",$M8="ERR",$J8="",$K8="",$N8=""),0,IF($N8=0,IF(AND(OR(4=7,4=12),4>=$K8,4<=IF($L8="",12,$L8)),$J8,0),IF(AND(4>=$K8,4<=IF($L8="",12,$L8),MOD(4-$K8,$N8)=0),$J8,0))) -> 113 | S8: =IF(OR($M8="",$M8="ERR",$J8="",$K8="",$N8=""),0,IF($N8=0,IF(AND(OR(5=7,5=12),5>=$K8,5<=IF($L8="",12,$L8)),$J8,0),IF(AND(5>=$K8,5<=IF($L8="",12,$L8),MOD(5-$K8,$N8)=0),$J8,0))) -> 113 | T8: =IF(OR($M8="",$M8="ERR",$J8="",$K8="",$N8=""),0,IF($N8=0,IF(AND(OR(6=7,6=12),6>=$K8,6<=IF($L8="",12,$L8)),$J8,0),IF(AND(6>=$K8,6<=IF($L8="",12,$L8),MOD(6-$K8,$N8)=0),$J8,0))) -> 113 | U8: =IF(OR($M8="",$M8="ERR",$J8="",$K8="",$N8=""),0,IF($N8=0,IF(AND(OR(7=7,7=12),7>=$K8,7<=IF($L8="",12,$L8)),$J8,0),IF(AND(7>=$K8,7<=IF($L8="",12,$L8),MOD(7-$K8,$N8)=0),$J8,0))) -> 113 | V8: =IF(OR($M8="",$M8="ERR",$J8="",$K8="",$N8=""),0,IF($N8=0,IF(AND(OR(8=7,8=12),8>=$K8,8<=IF($L8="",12,$L8)),$J8,0),IF(AND(8>=$K8,8<=IF($L8="",12,$L8),MOD(8-$K8,$N8)=0),$J8,0))) -> 113 | W8: =IF(OR($M8="",$M8="ERR",$J8="",$K8="",$N8=""),0,IF($N8=0,IF(AND(OR(9=7,9=12),9>=$K8,9<=IF($L8="",12,$L8)),$J8,0),IF(AND(9>=$K8,9<=IF($L8="",12,$L8),MOD(9-$K8,$N8)=0),$J8,0))) -> 113 | X8: =IF(OR($M8="",$M8="ERR",$J8="",$K8="",$N8=""),0,IF($N8=0,IF(AND(OR(10=7,10=12),10>=$K8,10<=IF($L8="",12,$L8)),$J8,0),IF(AND(10>=$K8,10<=IF($L8="",12,$L8),MOD(10-$K8,$N8)=0),$J8,0))) -> 113 | Y8: =IF(OR($M8="",$M8="ERR",$J8="",$K8="",$N8=""),0,IF($N8=0,IF(AND(OR(11=7,11=12),11>=$K8,11<=IF($L8="",12,$L8)),$J8,0),IF(AND(11>=$K8,11<=IF($L8="",12,$L8),MOD(11-$K8,$N8)=0),$J8,0))) -> 113 | Z8: =IF(OR($M8="",$M8="ERR",$J8="",$K8="",$N8=""),0,IF($N8=0,IF(AND(OR(12=7,12=12),12>=$K8,12<=IF($L8="",12,$L8)),$J8,0),IF(AND(12>=$K8,12<=IF($L8="",12,$L8),MOD(12-$K8,$N8)=0),$J8,0))) -> 113 | AA8: =SUM(O8:Z8) -> 1356 | AB8: =IF(AND($B8="",$D8="",$J8=""),"",IF($B8="","Falta código",IF(ISNA(MATCH($B8,LST_COD,0)),"Código no registrado en Trabajadores",IF($E8="","Concepto no está en el catálogo",IF($M8="ERR","Retención de otro empleador: Origen = Otro empleador",IF(OR($J8="",$K8=""),"Falta monto o mes",IF(OR($K8<1,$K8>12),"Mes inicio inválido",IF(AND($L8<>"",OR($L8<$K8,$L8>12)),"Mes fin inválido",IF($N8="","Falta frecuencia",IF(AND($G8<>"Otro empleador",SUMPRODUCT(($O8:$Z8<>0)*(((COLUMN($O8:$Z8)-14)<INDEX(Trabajadores!$M$6:$M$105,MATCH($B8,LST_COD,0)))+((COLUMN($O8:$Z8)-14)>INDEX(Trabajadores!$N$6:$N$105,MATCH($B8,LST_COD,0)))))>0),"Aviso: hay meses fuera del periodo laboral","OK")))))))))) -> OK
A9: 4 | B9: EJ-001 | C9: =IF($B9="","",IFERROR(INDEX(Trabajadores!$D$6:$D$105,MATCH($B9,LST_COD,0)),"¿Código?")) -> PÉREZ GARCÍA, ANA (EJEMPLO) | D9: Gratificación ordinaria (Fiestas Patrias / Navidad) | E9: =IF($D9="","",IFERROR(VLOOKUP($D9,CONC_TABLA,2,FALSE()),"")) -> GRA | F9: =IF($D9="","",IFERROR(VLOOKUP($D9,CONC_TABLA,3,FALSE()),"")) -> No | G9: Empresa principal | I9: Julio y Diciembre | J9: 9113 | K9: 1 | L9: 12 | M9: =IF(OR($B9="",$E9=""),"",IF($E9="INA","INA",IF($G9="Otro empleador",IF($E9="RET","RETO",IF($E9="ORD","OTO","OTX")),IF($E9="RET","ERR",$E9)))) -> GRA | N9: =IF($I9="","",IFERROR(VLOOKUP($I9,FREC_TABLA,2,FALSE()),"")) -> 0 | O9: =IF(OR($M9="",$M9="ERR",$J9="",$K9="",$N9=""),0,IF($N9=0,IF(AND(OR(1=7,1=12),1>=$K9,1<=IF($L9="",12,$L9)),$J9,0),IF(AND(1>=$K9,1<=IF($L9="",12,$L9),MOD(1-$K9,$N9)=0),$J9,0))) -> 0 | P9: =IF(OR($M9="",$M9="ERR",$J9="",$K9="",$N9=""),0,IF($N9=0,IF(AND(OR(2=7,2=12),2>=$K9,2<=IF($L9="",12,$L9)),$J9,0),IF(AND(2>=$K9,2<=IF($L9="",12,$L9),MOD(2-$K9,$N9)=0),$J9,0))) -> 0 | Q9: =IF(OR($M9="",$M9="ERR",$J9="",$K9="",$N9=""),0,IF($N9=0,IF(AND(OR(3=7,3=12),3>=$K9,3<=IF($L9="",12,$L9)),$J9,0),IF(AND(3>=$K9,3<=IF($L9="",12,$L9),MOD(3-$K9,$N9)=0),$J9,0))) -> 0 | R9: =IF(OR($M9="",$M9="ERR",$J9="",$K9="",$N9=""),0,IF($N9=0,IF(AND(OR(4=7,4=12),4>=$K9,4<=IF($L9="",12,$L9)),$J9,0),IF(AND(4>=$K9,4<=IF($L9="",12,$L9),MOD(4-$K9,$N9)=0),$J9,0))) -> 0 | S9: =IF(OR($M9="",$M9="ERR",$J9="",$K9="",$N9=""),0,IF($N9=0,IF(AND(OR(5=7,5=12),5>=$K9,5<=IF($L9="",12,$L9)),$J9,0),IF(AND(5>=$K9,5<=IF($L9="",12,$L9),MOD(5-$K9,$N9)=0),$J9,0))) -> 0 | T9: =IF(OR($M9="",$M9="ERR",$J9="",$K9="",$N9=""),0,IF($N9=0,IF(AND(OR(6=7,6=12),6>=$K9,6<=IF($L9="",12,$L9)),$J9,0),IF(AND(6>=$K9,6<=IF($L9="",12,$L9),MOD(6-$K9,$N9)=0),$J9,0))) -> 0 | U9: =IF(OR($M9="",$M9="ERR",$J9="",$K9="",$N9=""),0,IF($N9=0,IF(AND(OR(7=7,7=12),7>=$K9,7<=IF($L9="",12,$L9)),$J9,0),IF(AND(7>=$K9,7<=IF($L9="",12,$L9),MOD(7-$K9,$N9)=0),$J9,0))) -> 9113 | V9: =IF(OR($M9="",$M9="ERR",$J9="",$K9="",$N9=""),0,IF($N9=0,IF(AND(OR(8=7,8=12),8>=$K9,8<=IF($L9="",12,$L9)),$J9,0),IF(AND(8>=$K9,8<=IF($L9="",12,$L9),MOD(8-$K9,$N9)=0),$J9,0))) -> 0 | W9: =IF(OR($M9="",$M9="ERR",$J9="",$K9="",$N9=""),0,IF($N9=0,IF(AND(OR(9=7,9=12),9>=$K9,9<=IF($L9="",12,$L9)),$J9,0),IF(AND(9>=$K9,9<=IF($L9="",12,$L9),MOD(9-$K9,$N9)=0),$J9,0))) -> 0 | X9: =IF(OR($M9="",$M9="ERR",$J9="",$K9="",$N9=""),0,IF($N9=0,IF(AND(OR(10=7,10=12),10>=$K9,10<=IF($L9="",12,$L9)),$J9,0),IF(AND(10>=$K9,10<=IF($L9="",12,$L9),MOD(10-$K9,$N9)=0),$J9,0))) -> 0 | Y9: =IF(OR($M9="",$M9="ERR",$J9="",$K9="",$N9=""),0,IF($N9=0,IF(AND(OR(11=7,11=12),11>=$K9,11<=IF($L9="",12,$L9)),$J9,0),IF(AND(11>=$K9,11<=IF($L9="",12,$L9),MOD(11-$K9,$N9)=0),$J9,0))) -> 0 | Z9: =IF(OR($M9="",$M9="ERR",$J9="",$K9="",$N9=""),0,IF($N9=0,IF(AND(OR(12=7,12=12),12>=$K9,12<=IF($L9="",12,$L9)),$J9,0),IF(AND(12>=$K9,12<=IF($L9="",12,$L9),MOD(12-$K9,$N9)=0),$J9,0))) -> 9113 | AA9: =SUM(O9:Z9) -> 18226 | AB9: =IF(AND($B9="",$D9="",$J9=""),"",IF($B9="","Falta código",IF(ISNA(MATCH($B9,LST_COD,0)),"Código no registrado en Trabajadores",IF($E9="","Concepto no está en el catálogo",IF($M9="ERR","Retención de otro empleador: Origen = Otro empleador",IF(OR($J9="",$K9=""),"Falta monto o mes",IF(OR($K9<1,$K9>12),"Mes inicio inválido",IF(AND($L9<>"",OR($L9<$K9,$L9>12)),"Mes fin inválido",IF($N9="","Falta frecuencia",IF(AND($G9<>"Otro empleador",SUMPRODUCT(($O9:$Z9<>0)*(((COLUMN($O9:$Z9)-14)<INDEX(Trabajadores!$M$6:$M$105,MATCH($B9,LST_COD,0)))+((COLUMN($O9:$Z9)-14)>INDEX(Trabajadores!$N$6:$N$105,MATCH($B9,LST_COD,0)))))>0),"Aviso: hay meses fuera del periodo laboral","OK")))))))))) -> OK
A10: 5 | B10: EJ-001 | C10: =IF($B10="","",IFERROR(INDEX(Trabajadores!$D$6:$D$105,MATCH($B10,LST_COD,0)),"¿Código?")) -> PÉREZ GARCÍA, ANA (EJEMPLO) | D10: Bonificación extraordinaria Ley 30334 (9% / 6.75%) | E10: =IF($D10="","",IFERROR(VLOOKUP($D10,CONC_TABLA,2,FALSE()),"")) -> BON | F10: =IF($D10="","",IFERROR(VLOOKUP($D10,CONC_TABLA,3,FALSE()),"")) -> No | G10: Empresa principal | I10: Julio y Diciembre | J10: 820.17 | K10: 1 | L10: 12 | M10: =IF(OR($B10="",$E10=""),"",IF($E10="INA","INA",IF($G10="Otro empleador",IF($E10="RET","RETO",IF($E10="ORD","OTO","OTX")),IF($E10="RET","ERR",$E10)))) -> BON | N10: =IF($I10="","",IFERROR(VLOOKUP($I10,FREC_TABLA,2,FALSE()),"")) -> 0 | O10: =IF(OR($M10="",$M10="ERR",$J10="",$K10="",$N10=""),0,IF($N10=0,IF(AND(OR(1=7,1=12),1>=$K10,1<=IF($L10="",12,$L10)),$J10,0),IF(AND(1>=$K10,1<=IF($L10="",12,$L10),MOD(1-$K10,$N10)=0),$J10,0))) -> 0 | P10: =IF(OR($M10="",$M10="ERR",$J10="",$K10="",$N10=""),0,IF($N10=0,IF(AND(OR(2=7,2=12),2>=$K10,2<=IF($L10="",12,$L10)),$J10,0),IF(AND(2>=$K10,2<=IF($L10="",12,$L10),MOD(2-$K10,$N10)=0),$J10,0))) -> 0 | Q10: =IF(OR($M10="",$M10="ERR",$J10="",$K10="",$N10=""),0,IF($N10=0,IF(AND(OR(3=7,3=12),3>=$K10,3<=IF($L10="",12,$L10)),$J10,0),IF(AND(3>=$K10,3<=IF($L10="",12,$L10),MOD(3-$K10,$N10)=0),$J10,0))) -> 0 | R10: =IF(OR($M10="",$M10="ERR",$J10="",$K10="",$N10=""),0,IF($N10=0,IF(AND(OR(4=7,4=12),4>=$K10,4<=IF($L10="",12,$L10)),$J10,0),IF(AND(4>=$K10,4<=IF($L10="",12,$L10),MOD(4-$K10,$N10)=0),$J10,0))) -> 0 | S10: =IF(OR($M10="",$M10="ERR",$J10="",$K10="",$N10=""),0,IF($N10=0,IF(AND(OR(5=7,5=12),5>=$K10,5<=IF($L10="",12,$L10)),$J10,0),IF(AND(5>=$K10,5<=IF($L10="",12,$L10),MOD(5-$K10,$N10)=0),$J10,0))) -> 0 | T10: =IF(OR($M10="",$M10="ERR",$J10="",$K10="",$N10=""),0,IF($N10=0,IF(AND(OR(6=7,6=12),6>=$K10,6<=IF($L10="",12,$L10)),$J10,0),IF(AND(6>=$K10,6<=IF($L10="",12,$L10),MOD(6-$K10,$N10)=0),$J10,0))) -> 0 | U10: =IF(OR($M10="",$M10="ERR",$J10="",$K10="",$N10=""),0,IF($N10=0,IF(AND(OR(7=7,7=12),7>=$K10,7<=IF($L10="",12,$L10)),$J10,0),IF(AND(7>=$K10,7<=IF($L10="",12,$L10),MOD(7-$K10,$N10)=0),$J10,0))) -> 820.17 | V10: =IF(OR($M10="",$M10="ERR",$J10="",$K10="",$N10=""),0,IF($N10=0,IF(AND(OR(8=7,8=12),8>=$K10,8<=IF($L10="",12,$L10)),$J10,0),IF(AND(8>=$K10,8<=IF($L10="",12,$L10),MOD(8-$K10,$N10)=0),$J10,0))) -> 0 | W10: =IF(OR($M10="",$M10="ERR",$J10="",$K10="",$N10=""),0,IF($N10=0,IF(AND(OR(9=7,9=12),9>=$K10,9<=IF($L10="",12,$L10)),$J10,0),IF(AND(9>=$K10,9<=IF($L10="",12,$L10),MOD(9-$K10,$N10)=0),$J10,0))) -> 0 | X10: =IF(OR($M10="",$M10="ERR",$J10="",$K10="",$N10=""),0,IF($N10=0,IF(AND(OR(10=7,10=12),10>=$K10,10<=IF($L10="",12,$L10)),$J10,0),IF(AND(10>=$K10,10<=IF($L10="",12,$L10),MOD(10-$K10,$N10)=0),$J10,0))) -> 0 | Y10: =IF(OR($M10="",$M10="ERR",$J10="",$K10="",$N10=""),0,IF($N10=0,IF(AND(OR(11=7,11=12),11>=$K10,11<=IF($L10="",12,$L10)),$J10,0),IF(AND(11>=$K10,11<=IF($L10="",12,$L10),MOD(11-$K10,$N10)=0),$J10,0))) -> 0 | Z10: =IF(OR($M10="",$M10="ERR",$J10="",$K10="",$N10=""),0,IF($N10=0,IF(AND(OR(12=7,12=12),12>=$K10,12<=IF($L10="",12,$L10)),$J10,0),IF(AND(12>=$K10,12<=IF($L10="",12,$L10),MOD(12-$K10,$N10)=0),$J10,0))) -> 820.17 | AA10: =SUM(O10:Z10) -> 1640.34 | AB10: =IF(AND($B10="",$D10="",$J10=""),"",IF($B10="","Falta código",IF(ISNA(MATCH($B10,LST_COD,0)),"Código no registrado en Trabajadores",IF($E10="","Concepto no está en el catálogo",IF($M10="ERR","Retención de otro empleador: Origen = Otro empleador",IF(OR($J10="",$K10=""),"Falta monto o mes",IF(OR($K10<1,$K10>12),"Mes inicio inválido",IF(AND($L10<>"",OR($L10<$K10,$L10>12)),"Mes fin inválido",IF($N10="","Falta frecuencia",IF(AND($G10<>"Otro empleador",SUMPRODUCT(($O10:$Z10<>0)*(((COLUMN($O10:$Z10)-14)<INDEX(Trabajadores!$M$6:$M$105,MATCH($B10,LST_COD,0)))+((COLUMN($O10:$Z10)-14)>INDEX(Trabajadores!$N$6:$N$105,MATCH($B10,LST_COD,0)))))>0),"Aviso: hay meses fuera del periodo laboral","OK")))))))))) -> OK
A11: 6 | B11: EJ-001 | C11: =IF($B11="","",IFERROR(INDEX(Trabajadores!$D$6:$D$105,MATCH($B11,LST_COD,0)),"¿Código?")) -> PÉREZ GARCÍA, ANA (EJEMPLO) | D11: Participación en las utilidades | E11: =IF($D11="","",IFERROR(VLOOKUP($D11,CONC_TABLA,2,FALSE()),"")) -> EXT | F11: =IF($D11="","",IFERROR(VLOOKUP($D11,CONC_TABLA,3,FALSE()),"")) -> No | G11: Empresa principal | I11: Pago único | J11: 12000 | K11: 4 | M11: =IF(OR($B11="",$E11=""),"",IF($E11="INA","INA",IF($G11="Otro empleador",IF($E11="RET","RETO",IF($E11="ORD","OTO","OTX")),IF($E11="RET","ERR",$E11)))) -> EXT | N11: =IF($I11="","",IFERROR(VLOOKUP($I11,FREC_TABLA,2,FALSE()),"")) -> 12 | O11: =IF(OR($M11="",$M11="ERR",$J11="",$K11="",$N11=""),0,IF($N11=0,IF(AND(OR(1=7,1=12),1>=$K11,1<=IF($L11="",12,$L11)),$J11,0),IF(AND(1>=$K11,1<=IF($L11="",12,$L11),MOD(1-$K11,$N11)=0),$J11,0))) -> 0 | P11: =IF(OR($M11="",$M11="ERR",$J11="",$K11="",$N11=""),0,IF($N11=0,IF(AND(OR(2=7,2=12),2>=$K11,2<=IF($L11="",12,$L11)),$J11,0),IF(AND(2>=$K11,2<=IF($L11="",12,$L11),MOD(2-$K11,$N11)=0),$J11,0))) -> 0 | Q11: =IF(OR($M11="",$M11="ERR",$J11="",$K11="",$N11=""),0,IF($N11=0,IF(AND(OR(3=7,3=12),3>=$K11,3<=IF($L11="",12,$L11)),$J11,0),IF(AND(3>=$K11,3<=IF($L11="",12,$L11),MOD(3-$K11,$N11)=0),$J11,0))) -> 0 | R11: =IF(OR($M11="",$M11="ERR",$J11="",$K11="",$N11=""),0,IF($N11=0,IF(AND(OR(4=7,4=12),4>=$K11,4<=IF($L11="",12,$L11)),$J11,0),IF(AND(4>=$K11,4<=IF($L11="",12,$L11),MOD(4-$K11,$N11)=0),$J11,0))) -> 12000 | S11: =IF(OR($M11="",$M11="ERR",$J11="",$K11="",$N11=""),0,IF($N11=0,IF(AND(OR(5=7,5=12),5>=$K11,5<=IF($L11="",12,$L11)),$J11,0),IF(AND(5>=$K11,5<=IF($L11="",12,$L11),MOD(5-$K11,$N11)=0),$J11,0))) -> 0 | T11: =IF(OR($M11="",$M11="ERR",$J11="",$K11="",$N11=""),0,IF($N11=0,IF(AND(OR(6=7,6=12),6>=$K11,6<=IF($L11="",12,$L11)),$J11,0),IF(AND(6>=$K11,6<=IF($L11="",12,$L11),MOD(6-$K11,$N11)=0),$J11,0))) -> 0 | U11: =IF(OR($M11="",$M11="ERR",$J11="",$K11="",$N11=""),0,IF($N11=0,IF(AND(OR(7=7,7=12),7>=$K11,7<=IF($L11="",12,$L11)),$J11,0),IF(AND(7>=$K11,7<=IF($L11="",12,$L11),MOD(7-$K11,$N11)=0),$J11,0))) -> 0 | V11: =IF(OR($M11="",$M11="ERR",$J11="",$K11="",$N11=""),0,IF($N11=0,IF(AND(OR(8=7,8=12),8>=$K11,8<=IF($L11="",12,$L11)),$J11,0),IF(AND(8>=$K11,8<=IF($L11="",12,$L11),MOD(8-$K11,$N11)=0),$J11,0))) -> 0 | W11: =IF(OR($M11="",$M11="ERR",$J11="",$K11="",$N11=""),0,IF($N11=0,IF(AND(OR(9=7,9=12),9>=$K11,9<=IF($L11="",12,$L11)),$J11,0),IF(AND(9>=$K11,9<=IF($L11="",12,$L11),MOD(9-$K11,$N11)=0),$J11,0))) -> 0 | X11: =IF(OR($M11="",$M11="ERR",$J11="",$K11="",$N11=""),0,IF($N11=0,IF(AND(OR(10=7,10=12),10>=$K11,10<=IF($L11="",12,$L11)),$J11,0),IF(AND(10>=$K11,10<=IF($L11="",12,$L11),MOD(10-$K11,$N11)=0),$J11,0))) -> 0 | Y11: =IF(OR($M11="",$M11="ERR",$J11="",$K11="",$N11=""),0,IF($N11=0,IF(AND(OR(11=7,11=12),11>=$K11,11<=IF($L11="",12,$L11)),$J11,0),IF(AND(11>=$K11,11<=IF($L11="",12,$L11),MOD(11-$K11,$N11)=0),$J11,0))) -> 0 | Z11: =IF(OR($M11="",$M11="ERR",$J11="",$K11="",$N11=""),0,IF($N11=0,IF(AND(OR(12=7,12=12),12>=$K11,12<=IF($L11="",12,$L11)),$J11,0),IF(AND(12>=$K11,12<=IF($L11="",12,$L11),MOD(12-$K11,$N11)=0),$J11,0))) -> 0 | AA11: =SUM(O11:Z11) -> 12000 | AB11: =IF(AND($B11="",$D11="",$J11=""),"",IF($B11="","Falta código",IF(ISNA(MATCH($B11,LST_COD,0)),"Código no registrado en Trabajadores",IF($E11="","Concepto no está en el catálogo",IF($M11="ERR","Retención de otro empleador: Origen = Otro empleador",IF(OR($J11="",$K11=""),"Falta monto o mes",IF(OR($K11<1,$K11>12),"Mes inicio inválido",IF(AND($L11<>"",OR($L11<$K11,$L11>12)),"Mes fin inválido",IF($N11="","Falta frecuencia",IF(AND($G11<>"Otro empleador",SUMPRODUCT(($O11:$Z11<>0)*(((COLUMN($O11:$Z11)-14)<INDEX(Trabajadores!$M$6:$M$105,MATCH($B11,LST_COD,0)))+((COLUMN($O11:$Z11)-14)>INDEX(Trabajadores!$N$6:$N$105,MATCH($B11,LST_COD,0)))))>0),"Aviso: hay meses fuera del periodo laboral","OK")))))))))) -> OK
A12: 7 | B12: EJ-001 | C12: =IF($B12="","",IFERROR(INDEX(Trabajadores!$D$6:$D$105,MATCH($B12,LST_COD,0)),"¿Código?")) -> PÉREZ GARCÍA, ANA (EJEMPLO) | D12: Bono semestral (productividad, metas, etc.) | E12: =IF($D12="","",IFERROR(VLOOKUP($D12,CONC_TABLA,2,FALSE()),"")) -> EXT | F12: =IF($D12="","",IFERROR(VLOOKUP($D12,CONC_TABLA,3,FALSE()),"")) -> No | G12: Empresa principal | I12: Semestral | J12: 2500 | K12: 6 | L12: 12 | M12: =IF(OR($B12="",$E12=""),"",IF($E12="INA","INA",IF($G12="Otro empleador",IF($E12="RET","RETO",IF($E12="ORD","OTO","OTX")),IF($E12="RET","ERR",$E12)))) -> EXT | N12: =IF($I12="","",IFERROR(VLOOKUP($I12,FREC_TABLA,2,FALSE()),"")) -> 6 | O12: =IF(OR($M12="",$M12="ERR",$J12="",$K12="",$N12=""),0,IF($N12=0,IF(AND(OR(1=7,1=12),1>=$K12,1<=IF($L12="",12,$L12)),$J12,0),IF(AND(1>=$K12,1<=IF($L12="",12,$L12),MOD(1-$K12,$N12)=0),$J12,0))) -> 0 | P12: =IF(OR($M12="",$M12="ERR",$J12="",$K12="",$N12=""),0,IF($N12=0,IF(AND(OR(2=7,2=12),2>=$K12,2<=IF($L12="",12,$L12)),$J12,0),IF(AND(2>=$K12,2<=IF($L12="",12,$L12),MOD(2-$K12,$N12)=0),$J12,0))) -> 0 | Q12: =IF(OR($M12="",$M12="ERR",$J12="",$K12="",$N12=""),0,IF($N12=0,IF(AND(OR(3=7,3=12),3>=$K12,3<=IF($L12="",12,$L12)),$J12,0),IF(AND(3>=$K12,3<=IF($L12="",12,$L12),MOD(3-$K12,$N12)=0),$J12,0))) -> 0 | R12: =IF(OR($M12="",$M12="ERR",$J12="",$K12="",$N12=""),0,IF($N12=0,IF(AND(OR(4=7,4=12),4>=$K12,4<=IF($L12="",12,$L12)),$J12,0),IF(AND(4>=$K12,4<=IF($L12="",12,$L12),MOD(4-$K12,$N12)=0),$J12,0))) -> 0 | S12: =IF(OR($M12="",$M12="ERR",$J12="",$K12="",$N12=""),0,IF($N12=0,IF(AND(OR(5=7,5=12),5>=$K12,5<=IF($L12="",12,$L12)),$J12,0),IF(AND(5>=$K12,5<=IF($L12="",12,$L12),MOD(5-$K12,$N12)=0),$J12,0))) -> 0 | T12: =IF(OR($M12="",$M12="ERR",$J12="",$K12="",$N12=""),0,IF($N12=0,IF(AND(OR(6=7,6=12),6>=$K12,6<=IF($L12="",12,$L12)),$J12,0),IF(AND(6>=$K12,6<=IF($L12="",12,$L12),MOD(6-$K12,$N12)=0),$J12,0))) -> 2500 | U12: =IF(OR($M12="",$M12="ERR",$J12="",$K12="",$N12=""),0,IF($N12=0,IF(AND(OR(7=7,7=12),7>=$K12,7<=IF($L12="",12,$L12)),$J12,0),IF(AND(7>=$K12,7<=IF($L12="",12,$L12),MOD(7-$K12,$N12)=0),$J12,0))) -> 0 | V12: =IF(OR($M12="",$M12="ERR",$J12="",$K12="",$N12=""),0,IF($N12=0,IF(AND(OR(8=7,8=12),8>=$K12,8<=IF($L12="",12,$L12)),$J12,0),IF(AND(8>=$K12,8<=IF($L12="",12,$L12),MOD(8-$K12,$N12)=0),$J12,0))) -> 0 | W12: =IF(OR($M12="",$M12="ERR",$J12="",$K12="",$N12=""),0,IF($N12=0,IF(AND(OR(9=7,9=12),9>=$K12,9<=IF($L12="",12,$L12)),$J12,0),IF(AND(9>=$K12,9<=IF($L12="",12,$L12),MOD(9-$K12,$N12)=0),$J12,0))) -> 0 | X12: =IF(OR($M12="",$M12="ERR",$J12="",$K12="",$N12=""),0,IF($N12=0,IF(AND(OR(10=7,10=12),10>=$K12,10<=IF($L12="",12,$L12)),$J12,0),IF(AND(10>=$K12,10<=IF($L12="",12,$L12),MOD(10-$K12,$N12)=0),$J12,0))) -> 0 | Y12: =IF(OR($M12="",$M12="ERR",$J12="",$K12="",$N12=""),0,IF($N12=0,IF(AND(OR(11=7,11=12),11>=$K12,11<=IF($L12="",12,$L12)),$J12,0),IF(AND(11>=$K12,11<=IF($L12="",12,$L12),MOD(11-$K12,$N12)=0),$J12,0))) -> 0 | Z12: =IF(OR($M12="",$M12="ERR",$J12="",$K12="",$N12=""),0,IF($N12=0,IF(AND(OR(12=7,12=12),12>=$K12,12<=IF($L12="",12,$L12)),$J12,0),IF(AND(12>=$K12,12<=IF($L12="",12,$L12),MOD(12-$K12,$N12)=0),$J12,0))) -> 2500 | AA12: =SUM(O12:Z12) -> 5000 | AB12: =IF(AND($B12="",$D12="",$J12=""),"",IF($B12="","Falta código",IF(ISNA(MATCH($B12,LST_COD,0)),"Código no registrado en Trabajadores",IF($E12="","Concepto no está en el catálogo",IF($M12="ERR","Retención de otro empleador: Origen = Otro empleador",IF(OR($J12="",$K12=""),"Falta monto o mes",IF(OR($K12<1,$K12>12),"Mes inicio inválido",IF(AND($L12<>"",OR($L12<$K12,$L12>12)),"Mes fin inválido",IF($N12="","Falta frecuencia",IF(AND($G12<>"Otro empleador",SUMPRODUCT(($O12:$Z12<>0)*(((COLUMN($O12:$Z12)-14)<INDEX(Trabajadores!$M$6:$M$105,MATCH($B12,LST_COD,0)))+((COLUMN($O12:$Z12)-14)>INDEX(Trabajadores!$N$6:$N$105,MATCH($B12,LST_COD,0)))))>0),"Aviso: hay meses fuera del periodo laboral","OK")))))))))) -> OK
A13: 8 | B13: EJ-001 | C13: =IF($B13="","",IFERROR(INDEX(Trabajadores!$D$6:$D$105,MATCH($B13,LST_COD,0)),"¿Código?")) -> PÉREZ GARCÍA, ANA (EJEMPLO) | D13: Bono trimestral (ventas, metas, etc.) | E13: =IF($D13="","",IFERROR(VLOOKUP($D13,CONC_TABLA,2,FALSE()),"")) -> EXT | F13: =IF($D13="","",IFERROR(VLOOKUP($D13,CONC_TABLA,3,FALSE()),"")) -> No | G13: Empresa principal | I13: Trimestral | J13: 1200 | K13: 3 | L13: 12 | M13: =IF(OR($B13="",$E13=""),"",IF($E13="INA","INA",IF($G13="Otro empleador",IF($E13="RET","RETO",IF($E13="ORD","OTO","OTX")),IF($E13="RET","ERR",$E13)))) -> EXT | N13: =IF($I13="","",IFERROR(VLOOKUP($I13,FREC_TABLA,2,FALSE()),"")) -> 3 | O13: =IF(OR($M13="",$M13="ERR",$J13="",$K13="",$N13=""),0,IF($N13=0,IF(AND(OR(1=7,1=12),1>=$K13,1<=IF($L13="",12,$L13)),$J13,0),IF(AND(1>=$K13,1<=IF($L13="",12,$L13),MOD(1-$K13,$N13)=0),$J13,0))) -> 0 | P13: =IF(OR($M13="",$M13="ERR",$J13="",$K13="",$N13=""),0,IF($N13=0,IF(AND(OR(2=7,2=12),2>=$K13,2<=IF($L13="",12,$L13)),$J13,0),IF(AND(2>=$K13,2<=IF($L13="",12,$L13),MOD(2-$K13,$N13)=0),$J13,0))) -> 0 | Q13: =IF(OR($M13="",$M13="ERR",$J13="",$K13="",$N13=""),0,IF($N13=0,IF(AND(OR(3=7,3=12),3>=$K13,3<=IF($L13="",12,$L13)),$J13,0),IF(AND(3>=$K13,3<=IF($L13="",12,$L13),MOD(3-$K13,$N13)=0),$J13,0))) -> 1200 | R13: =IF(OR($M13="",$M13="ERR",$J13="",$K13="",$N13=""),0,IF($N13=0,IF(AND(OR(4=7,4=12),4>=$K13,4<=IF($L13="",12,$L13)),$J13,0),IF(AND(4>=$K13,4<=IF($L13="",12,$L13),MOD(4-$K13,$N13)=0),$J13,0))) -> 0 | S13: =IF(OR($M13="",$M13="ERR",$J13="",$K13="",$N13=""),0,IF($N13=0,IF(AND(OR(5=7,5=12),5>=$K13,5<=IF($L13="",12,$L13)),$J13,0),IF(AND(5>=$K13,5<=IF($L13="",12,$L13),MOD(5-$K13,$N13)=0),$J13,0))) -> 0 | T13: =IF(OR($M13="",$M13="ERR",$J13="",$K13="",$N13=""),0,IF($N13=0,IF(AND(OR(6=7,6=12),6>=$K13,6<=IF($L13="",12,$L13)),$J13,0),IF(AND(6>=$K13,6<=IF($L13="",12,$L13),MOD(6-$K13,$N13)=0),$J13,0))) -> 1200 | U13: =IF(OR($M13="",$M13="ERR",$J13="",$K13="",$N13=""),0,IF($N13=0,IF(AND(OR(7=7,7=12),7>=$K13,7<=IF($L13="",12,$L13)),$J13,0),IF(AND(7>=$K13,7<=IF($L13="",12,$L13),MOD(7-$K13,$N13)=0),$J13,0))) -> 0 | V13: =IF(OR($M13="",$M13="ERR",$J13="",$K13="",$N13=""),0,IF($N13=0,IF(AND(OR(8=7,8=12),8>=$K13,8<=IF($L13="",12,$L13)),$J13,0),IF(AND(8>=$K13,8<=IF($L13="",12,$L13),MOD(8-$K13,$N13)=0),$J13,0))) -> 0 | W13: =IF(OR($M13="",$M13="ERR",$J13="",$K13="",$N13=""),0,IF($N13=0,IF(AND(OR(9=7,9=12),9>=$K13,9<=IF($L13="",12,$L13)),$J13,0),IF(AND(9>=$K13,9<=IF($L13="",12,$L13),MOD(9-$K13,$N13)=0),$J13,0))) -> 1200 | X13: =IF(OR($M13="",$M13="ERR",$J13="",$K13="",$N13=""),0,IF($N13=0,IF(AND(OR(10=7,10=12),10>=$K13,10<=IF($L13="",12,$L13)),$J13,0),IF(AND(10>=$K13,10<=IF($L13="",12,$L13),MOD(10-$K13,$N13)=0),$J13,0))) -> 0 | Y13: =IF(OR($M13="",$M13="ERR",$J13="",$K13="",$N13=""),0,IF($N13=0,IF(AND(OR(11=7,11=12),11>=$K13,11<=IF($L13="",12,$L13)),$J13,0),IF(AND(11>=$K13,11<=IF($L13="",12,$L13),MOD(11-$K13,$N13)=0),$J13,0))) -> 0 | Z13: =IF(OR($M13="",$M13="ERR",$J13="",$K13="",$N13=""),0,IF($N13=0,IF(AND(OR(12=7,12=12),12>=$K13,12<=IF($L13="",12,$L13)),$J13,0),IF(AND(12>=$K13,12<=IF($L13="",12,$L13),MOD(12-$K13,$N13)=0),$J13,0))) -> 1200 | AA13: =SUM(O13:Z13) -> 4800 | AB13: =IF(AND($B13="",$D13="",$J13=""),"",IF($B13="","Falta código",IF(ISNA(MATCH($B13,LST_COD,0)),"Código no registrado en Trabajadores",IF($E13="","Concepto no está en el catálogo",IF($M13="ERR","Retención de otro empleador: Origen = Otro empleador",IF(OR($J13="",$K13=""),"Falta monto o mes",IF(OR($K13<1,$K13>12),"Mes inicio inválido",IF(AND($L13<>"",OR($L13<$K13,$L13>12)),"Mes fin inválido",IF($N13="","Falta frecuencia",IF(AND($G13<>"Otro empleador",SUMPRODUCT(($O13:$Z13<>0)*(((COLUMN($O13:$Z13)-14)<INDEX(Trabajadores!$M$6:$M$105,MATCH($B13,LST_COD,0)))+((COLUMN($O13:$Z13)-14)>INDEX(Trabajadores!$N$6:$N$105,MATCH($B13,LST_COD,0)))))>0),"Aviso: hay meses fuera del periodo laboral","OK")))))))))) -> OK
